ERROR:asyncio:Task exception was never retrieved
future: <Task finished name='Task-4' coro=<Agent._process_message_queue() done, defined at /Users/darshanrao/Developer/ExploreEaseAI/venv/lib/python3.11/site-packages/uagents/agent.py:1222> exception=SystemExit(0)>
Traceback (most recent call last):
  File "/Users/darshanrao/Developer/ExploreEaseAI/venv/lib/python3.11/site-packages/uagents/agent.py", line 1209, in run
    self._loop.run_until_complete(self.run_async())
  File "/Users/darshanrao/anaconda3/lib/python3.11/asyncio/base_events.py", line 640, in run_until_complete
    self.run_forever()
  File "/Users/darshanrao/anaconda3/lib/python3.11/asyncio/base_events.py", line 607, in run_forever
    self._run_once()
  File "/Users/darshanrao/anaconda3/lib/python3.11/asyncio/base_events.py", line 1922, in _run_once
    handle._run()
  File "/Users/darshanrao/anaconda3/lib/python3.11/asyncio/events.py", line 80, in _run
    self._context.run(self._callback, *self._args)
  File "/Users/darshanrao/Developer/ExploreEaseAI/venv/lib/python3.11/site-packages/uagents/agent.py", line 1312, in _process_message_queue
    await handler(context, sender, recovered)
  File "/Users/darshanrao/Developer/ExploreEaseAI/client_agent.py", line 118, in handle_itinerary
    sys.exit(0)
SystemExit: 0
